2020-06-07 17:42:13,506 ERROR: Exception on /home [POST] [in c:\users\augus\appdata\local\programs\python\python38-32\lib\site-packages\flask\app.py:1891]
Traceback (most recent call last):
  File "c:\users\augus\appdata\local\programs\python\python38-32\lib\site-packages\sqlalchemy\engine\base.py", line 1211, in _execute_context
    context = constructor(dialect, self, conn, *args)
  File "c:\users\augus\appdata\local\programs\python\python38-32\lib\site-packages\sqlalchemy\engine\default.py", line 836, in _init_compiled
    param.append(processors[key](compiled_params[key]))
  File "c:\users\augus\appdata\local\programs\python\python38-32\lib\site-packages\sqlalchemy\sql\sqltypes.py", line 914, in process
    return DBAPIBinary(value)
TypeError: memoryview: a bytes-like object is required, not 'str'

The above exception was the direct cause of the following exception:

Traceback (most recent call last):
  File "c:\users\augus\appdata\local\programs\python\python38-32\lib\site-packages\flask\app.py", line 2447, in wsgi_app
    response = self.full_dispatch_request()
  File "c:\users\augus\appdata\local\programs\python\python38-32\lib\site-packages\flask\app.py", line 1952, in full_dispatch_request
    rv = self.handle_user_exception(e)
  File "c:\users\augus\appdata\local\programs\python\python38-32\lib\site-packages\flask\app.py", line 1821, in handle_user_exception
    reraise(exc_type, exc_value, tb)
  File "c:\users\augus\appdata\local\programs\python\python38-32\lib\site-packages\flask\_compat.py", line 39, in reraise
    raise value
  File "c:\users\augus\appdata\local\programs\python\python38-32\lib\site-packages\flask\app.py", line 1950, in full_dispatch_request
    rv = self.dispatch_request()
  File "c:\users\augus\appdata\local\programs\python\python38-32\lib\site-packages\flask\app.py", line 1936, in dispatch_request
    return self.view_functions[rule.endpoint](**req.view_args)
  File "c:\users\augus\appdata\local\programs\python\python38-32\lib\site-packages\flask_login\utils.py", line 272, in decorated_view
    return func(*args, **kwargs)
  File "C:\Users\augus\OneDrive\Skrivebord\CratesAppFeature\app\routes.py", line 26, in index
    db.session.commit()
  File "c:\users\augus\appdata\local\programs\python\python38-32\lib\site-packages\sqlalchemy\orm\scoping.py", line 163, in do
    return getattr(self.registry(), name)(*args, **kwargs)
  File "c:\users\augus\appdata\local\programs\python\python38-32\lib\site-packages\sqlalchemy\orm\session.py", line 1042, in commit
    self.transaction.commit()
  File "c:\users\augus\appdata\local\programs\python\python38-32\lib\site-packages\sqlalchemy\orm\session.py", line 504, in commit
    self._prepare_impl()
  File "c:\users\augus\appdata\local\programs\python\python38-32\lib\site-packages\sqlalchemy\orm\session.py", line 483, in _prepare_impl
    self.session.flush()
  File "c:\users\augus\appdata\local\programs\python\python38-32\lib\site-packages\sqlalchemy\orm\session.py", line 2523, in flush
    self._flush(objects)
  File "c:\users\augus\appdata\local\programs\python\python38-32\lib\site-packages\sqlalchemy\orm\session.py", line 2664, in _flush
    transaction.rollback(_capture_exception=True)
  File "c:\users\augus\appdata\local\programs\python\python38-32\lib\site-packages\sqlalchemy\util\langhelpers.py", line 68, in __exit__
    compat.raise_(
  File "c:\users\augus\appdata\local\programs\python\python38-32\lib\site-packages\sqlalchemy\util\compat.py", line 178, in raise_
    raise exception
  File "c:\users\augus\appdata\local\programs\python\python38-32\lib\site-packages\sqlalchemy\orm\session.py", line 2624, in _flush
    flush_context.execute()
  File "c:\users\augus\appdata\local\programs\python\python38-32\lib\site-packages\sqlalchemy\orm\unitofwork.py", line 422, in execute
    rec.execute(self)
  File "c:\users\augus\appdata\local\programs\python\python38-32\lib\site-packages\sqlalchemy\orm\unitofwork.py", line 586, in execute
    persistence.save_obj(
  File "c:\users\augus\appdata\local\programs\python\python38-32\lib\site-packages\sqlalchemy\orm\persistence.py", line 239, in save_obj
    _emit_insert_statements(
  File "c:\users\augus\appdata\local\programs\python\python38-32\lib\site-packages\sqlalchemy\orm\persistence.py", line 1135, in _emit_insert_statements
    result = cached_connections[connection].execute(
  File "c:\users\augus\appdata\local\programs\python\python38-32\lib\site-packages\sqlalchemy\engine\base.py", line 1020, in execute
    return meth(self, multiparams, params)
  File "c:\users\augus\appdata\local\programs\python\python38-32\lib\site-packages\sqlalchemy\sql\elements.py", line 298, in _execute_on_connection
    return connection._execute_clauseelement(self, multiparams, params)
  File "c:\users\augus\appdata\local\programs\python\python38-32\lib\site-packages\sqlalchemy\engine\base.py", line 1133, in _execute_clauseelement
    ret = self._execute_context(
  File "c:\users\augus\appdata\local\programs\python\python38-32\lib\site-packages\sqlalchemy\engine\base.py", line 1213, in _execute_context
    self._handle_dbapi_exception(
  File "c:\users\augus\appdata\local\programs\python\python38-32\lib\site-packages\sqlalchemy\engine\base.py", line 1517, in _handle_dbapi_exception
    util.raise_(
  File "c:\users\augus\appdata\local\programs\python\python38-32\lib\site-packages\sqlalchemy\util\compat.py", line 178, in raise_
    raise exception
  File "c:\users\augus\appdata\local\programs\python\python38-32\lib\site-packages\sqlalchemy\engine\base.py", line 1211, in _execute_context
    context = constructor(dialect, self, conn, *args)
  File "c:\users\augus\appdata\local\programs\python\python38-32\lib\site-packages\sqlalchemy\engine\default.py", line 836, in _init_compiled
    param.append(processors[key](compiled_params[key]))
  File "c:\users\augus\appdata\local\programs\python\python38-32\lib\site-packages\sqlalchemy\sql\sqltypes.py", line 914, in process
    return DBAPIBinary(value)
sqlalchemy.exc.StatementError: (builtins.TypeError) memoryview: a bytes-like object is required, not 'str'
[SQL: INSERT INTO post (body, price, timestamp, user_id, image) VALUES (?, ?, ?, ?, ?)]
[parameters: [{'image': 'C:\\Users\\augus\\OneDrive\\Skrivebord\\CratesAppFeature\\app\\static\\7511f618-a8d5-11ea-b489-01198600a73f', 'user_id': 1, 'price': '119.95', 'body': 'VitaYummy Hair & Nails 60\xa0stk.'}]]
2020-06-07 17:43:38,259 INFO: Crates startup [in C:\Users\augus\OneDrive\Skrivebord\CratesAppFeature\app\__init__.py:30]
2020-06-07 17:43:45,364 INFO: Crates startup [in C:\Users\augus\OneDrive\Skrivebord\CratesAppFeature\app\__init__.py:30]
2020-06-07 17:44:03,586 INFO: Crates startup [in C:\Users\augus\OneDrive\Skrivebord\CratesAppFeature\app\__init__.py:30]
2020-06-07 17:45:14,685 INFO: Crates startup [in C:\Users\augus\OneDrive\Skrivebord\CratesAppFeature\app\__init__.py:30]
2020-06-07 17:45:24,091 ERROR: Exception on /home [GET] [in c:\users\augus\appdata\local\programs\python\python38-32\lib\site-packages\flask\app.py:1891]
Traceback (most recent call last):
  File "c:\users\augus\appdata\local\programs\python\python38-32\lib\site-packages\flask\app.py", line 2447, in wsgi_app
    response = self.full_dispatch_request()
  File "c:\users\augus\appdata\local\programs\python\python38-32\lib\site-packages\flask\app.py", line 1952, in full_dispatch_request
    rv = self.handle_user_exception(e)
  File "c:\users\augus\appdata\local\programs\python\python38-32\lib\site-packages\flask\app.py", line 1821, in handle_user_exception
    reraise(exc_type, exc_value, tb)
  File "c:\users\augus\appdata\local\programs\python\python38-32\lib\site-packages\flask\_compat.py", line 39, in reraise
    raise value
  File "c:\users\augus\appdata\local\programs\python\python38-32\lib\site-packages\flask\app.py", line 1950, in full_dispatch_request
    rv = self.dispatch_request()
  File "c:\users\augus\appdata\local\programs\python\python38-32\lib\site-packages\flask\app.py", line 1936, in dispatch_request
    return self.view_functions[rule.endpoint](**req.view_args)
  File "c:\users\augus\appdata\local\programs\python\python38-32\lib\site-packages\flask_login\utils.py", line 272, in decorated_view
    return func(*args, **kwargs)
  File "C:\Users\augus\OneDrive\Skrivebord\CratesAppFeature\app\routes.py", line 33, in index
    return render_template("index.html", title="Home", form=form, posts=posts, quantity=quantity)
  File "c:\users\augus\appdata\local\programs\python\python38-32\lib\site-packages\flask\templating.py", line 138, in render_template
    ctx.app.jinja_env.get_or_select_template(template_name_or_list),
  File "c:\users\augus\appdata\local\programs\python\python38-32\lib\site-packages\jinja2\environment.py", line 930, in get_or_select_template
    return self.get_template(template_name_or_list, parent, globals)
  File "c:\users\augus\appdata\local\programs\python\python38-32\lib\site-packages\jinja2\environment.py", line 883, in get_template
    return self._load_template(name, self.make_globals(globals))
  File "c:\users\augus\appdata\local\programs\python\python38-32\lib\site-packages\jinja2\environment.py", line 857, in _load_template
    template = self.loader.load(self, name, globals)
  File "c:\users\augus\appdata\local\programs\python\python38-32\lib\site-packages\jinja2\loaders.py", line 115, in load
    source, filename, uptodate = self.get_source(environment, name)
  File "c:\users\augus\appdata\local\programs\python\python38-32\lib\site-packages\flask\templating.py", line 60, in get_source
    return self._get_source_fast(environment, template)
  File "c:\users\augus\appdata\local\programs\python\python38-32\lib\site-packages\flask\templating.py", line 89, in _get_source_fast
    raise TemplateNotFound(template)
jinja2.exceptions.TemplateNotFound: index.html
2020-06-07 17:46:15,287 INFO: Crates startup [in C:\Users\augus\OneDrive\Skrivebord\CratesAppFeature\app\__init__.py:30]
2020-06-07 17:47:02,456 INFO: Crates startup [in C:\Users\augus\OneDrive\Skrivebord\CratesAppFeature\app\__init__.py:30]
